#VRML_SIM R2023b utf8

EXTERNPROTO "https://raw.githubusercontent.com/cyberbotics/webots/R2023b/projects/objects/backgrounds/protos/TexturedBackground.proto"
EXTERNPROTO "https://raw.githubusercontent.com/cyberbotics/webots/R2023b/projects/objects/backgrounds/protos/TexturedBackgroundLight.proto"
EXTERNPROTO "https://raw.githubusercontent.com/cyberbotics/webots/R2023b/projects/objects/floors/protos/Floor.proto"
EXTERNPROTO "../protos/wheg5.proto"
EXTERNPROTO "https://raw.githubusercontent.com/cyberbotics/webots/R2023b/projects/objects/floors/protos/UnevenTerrain.proto"
EXTERNPROTO "https://raw.githubusercontent.com/cyberbotics/webots/R2023b/projects/appearances/protos/FormedConcrete.proto"
EXTERNPROTO "https://raw.githubusercontent.com/cyberbotics/webots/R2023b/projects/appearances/protos/CorrodedMetal.proto"
EXTERNPROTO "https://raw.githubusercontent.com/cyberbotics/webots/R2023b/projects/objects/rocks/protos/Rock.proto"

WorldInfo {
  basicTimeStep 5
  FPS 200
  contactProperties [
    ContactProperties {
      material1 "block"
      material2 "arcs"
      coulombFriction [
        0.65
      ]
    }
    ContactProperties {
      material1 "arcs"
      material2 "floor"
      coulombFriction [
        0.65
      ]
      bounce 0
    }
  ]
}
Viewpoint {
  orientation -0.13577869247827348 -0.24520995225269468 0.9599146972440424 5.031720754402325
  position -0.7304911598557159 3.649941495665572 1.456656459995592
}
TexturedBackground {
}
TexturedBackgroundLight {
}
Floor {
  translation 0 0 -1
  contactMaterial "floor"
}
DEF whegs Robot {
  translation 0 0 0.17
  children [
    SliderJoint {
      jointParameters JointParameters {
        minStop -0.01
        maxStop 0.01
        springConstant 1000
        dampingConstant 1000
      }
      endPoint Solid {
        children [
          wheg5 {
            anchor 0.15 -0.26 -0.03
            in_motor_name "mi_01"
            out_motor_name "mo_01"
            plate_name "whl_xx(3)"
            hub_name "hub_xx(3)"
            in_sense_name "si_01"
            out_sense_name "so_01"
          }
        ]
        name "slider_empty(1)"
        physics Physics {
          density -1
          mass 0.001
          centerOfMass [
            0 0 0
          ]
          inertiaMatrix [
            0.1 0.1 0.1
            0 0 0
          ]
        }
      }
    }
    SliderJoint {
      jointParameters JointParameters {
        minStop -0.01
        maxStop 0.01
        springConstant 1000
        dampingConstant 1000
      }
      endPoint Solid {
        children [
          wheg5 {
            anchor -0.15 0.22 -0.03
            in_motor_name "mi_02"
            out_motor_name "mo_02"
            plate_name "whl_xx(2)"
            hub_name "hub_xx(2)"
            in_sense_name "si_02"
            out_sense_name "so_02"
          }
        ]
        name "slider_empty(2)"
        physics Physics {
          density -1
          mass 0.001
          centerOfMass [
            0 0 0
          ]
          inertiaMatrix [
            0.1 0.1 0.1
            0 0 0
          ]
        }
      }
    }
    SliderJoint {
      jointParameters JointParameters {
        minStop -0.01
        maxStop 0.01
        springConstant 1000
        dampingConstant 1000
      }
      endPoint Solid {
        children [
          wheg5 {
            anchor -0.16 -0.26 -0.03
            in_motor_name "mi_03"
            out_motor_name "mo_03"
            plate_name "whl_xx(1)"
            hub_name "hub_xx(1)"
            in_sense_name "si_03"
            out_sense_name "so_03"
          }
        ]
        name "slider_empty(3)"
        physics Physics {
          density -1
          mass 0.001
          centerOfMass [
            0 0 0
          ]
          inertiaMatrix [
            0.1 0.1 0.1
            0 0 0
          ]
        }
      }
    }
    SliderJoint {
      jointParameters JointParameters {
        minStop -0.01
        maxStop 0.01
        springConstant 1000
        dampingConstant 1000
      }
      endPoint Solid {
        children [
          wheg5 {
            anchor 0.15 0.22 -0.03
            in_motor_name "mi_00"
            out_motor_name "mo_00"
            in_sense_name "si_00"
            out_sense_name "so_00"
          }
        ]
        name "slider_empty"
        physics Physics {
          density -1
          mass 0.001
          centerOfMass [
            0 0 0
          ]
          inertiaMatrix [
            0.1 0.1 0.1
            0 0 0
          ]
        }
      }
    }
    HingeJoint {
      jointParameters HingeJointParameters {
        anchor 0.15 0.02 0
        springConstant 100
        dampingConstant 100
      }
      endPoint Solid {
        translation -0.155 -0.145 -0.02
        children [
          Shape {
            appearance DEF BoxColor PBRAppearance {
              baseColor 0.384314 0.627451 0.917647
              roughness 0.5
              metalness 0
            }
            geometry DEF drive_box_geo Box {
              size 0.15 0.124 0.068
            }
          }
        ]
        name "box3"
        boundingObject USE drive_box_geo
        physics Physics {
          density -1
          mass 0.3
        }
      }
    }
    HingeJoint {
      jointParameters HingeJointParameters {
        anchor 0.15 0.02 0
        springConstant 100
        dampingConstant 100
      }
      endPoint Solid {
        translation -0.155 0.145 -0.02
        children [
          Shape {
            appearance USE BoxColor
            geometry DEF drive_box_geo Box {
              size 0.15 0.124 0.068
            }
          }
        ]
        name "box2"
        boundingObject USE drive_box_geo
        physics Physics {
          density -1
          mass 0.3
        }
      }
    }
    HingeJoint {
      jointParameters HingeJointParameters {
        anchor 0.15 0.02 0
        springConstant 100
      }
      endPoint Solid {
        translation 0.155 -0.145 -0.02
        children [
          Shape {
            appearance USE BoxColor
            geometry DEF drive_box_geo Box {
              size 0.15 0.124 0.068
            }
          }
        ]
        name "box1"
        boundingObject USE drive_box_geo
        physics Physics {
          density -1
          mass 0.3
        }
      }
    }
    HingeJoint {
      jointParameters HingeJointParameters {
        anchor 0.15 0.02 0
        springConstant 100
      }
      endPoint Solid {
        translation 0.155 0.145 -0.02
        children [
          Shape {
            appearance USE BoxColor
            geometry DEF drive_box_geo Box {
              size 0.15 0.124 0.068
            }
          }
        ]
        name "box0"
        boundingObject USE drive_box_geo
        physics Physics {
          density -1
          mass 0.3
        }
      }
    }
    Solid {
      children [
        DEF frame_geo Group {
          children [
            Pose {
              translation 0.155 0.1185 0
              rotation 0 0 1 1.5708
              children [
                Shape {
                  appearance DEF FrameColor PBRAppearance {
                    baseColor 0.972549 0.894118 0.360784
                    roughness 0.8
                    metalness 0.2
                  }
                  geometry DEF leg-box_geo Box {
                    size 0.18 0.04 0.02
                  }
                }
              ]
            }
            Pose {
              translation -0.155 0.1185 0
              rotation 0 0 1 1.5708
              children [
                Shape {
                  appearance USE FrameColor
                  geometry USE leg-box_geo
                }
              ]
            }
            Pose {
              translation -0.155 -0.1185 0
              rotation 0 0 1 1.5708
              children [
                Shape {
                  appearance USE FrameColor
                  geometry USE leg-box_geo
                }
              ]
            }
            Pose {
              translation 0.155 -0.1185 0
              rotation 0 0 1 1.5708
              children [
                Shape {
                  appearance USE FrameColor
                  geometry USE leg-box_geo
                }
              ]
            }
            Shape {
              appearance USE FrameColor
              geometry DEF center_box_geo Box {
                size 0.4 0.04 0.04
              }
            }
          ]
        }
      ]
      name "frame"
    }
  ]
  boundingObject USE center_box_geo
  physics Physics {
    density -1
    mass 10
  }
  controller "wheg_ctrl_v"
}
Robot {
  name "supervisor"
  controller "supervisor_obstacles"
  supervisor TRUE
}
DEF ground UnevenTerrain {
  translation 1.68 0 -0.21
  size 5 5 0.5
  randomSeed 13
  perlinNOctaves 7
}
DEF block Solid {
  translation 0.85 0 -0.18
  children [
    DEF block_geo Group {
      children [
        Shape {
          appearance FormedConcrete {
          }
          geometry Box {
            size 0.7 2 0.18
          }
        }
      ]
    }
  ]
  contactMaterial "block"
  boundingObject USE block_geo
}
DEF pipeA Solid {
  translation 0.64 0 -0.1
  children [
    DEF pipe_geo Group {
      children [
        Pose {
          rotation 1 0 0 -1.5707953071795862
          children [
            Shape {
              appearance CorrodedMetal {
              }
              geometry Cylinder {
                radius 0.05
              }
            }
          ]
        }
      ]
    }
  ]
  name "pipea"
  contactMaterial "block"
  boundingObject USE pipe_geo
}
DEF rocks Pose {
  translation 0 0 -0.16
  children [
    Rock {
      translation 1.09807 0.21 -0.0605314
      rotation 0 1 0 1.8326
      name "rock(7)"
      scale 2
    }
    Rock {
      translation 0.956024 -0.299136 -0.0051965
      rotation -0.34819300999157266 -0.6030920173060272 0.7176640205937282 -2.7489653071795863
      name "rock(8)"
      scale 2
    }
    Rock {
      translation 0.96 0.07 -0.03
      rotation 0 0 1 -2.8797953071795863
      name "rock(5)"
      scale 2
    }
    Rock {
      translation 0.860026 -0.214753 -0.0373935
      rotation 0.7830049365033916 -0.6008209512773282 0.1609889869448401 -2.727985307179586
      name "rock(3)"
      scale 2
    }
    Rock {
      translation 0.57 -0.22 -0.03
      rotation -0.6215153336152258 0.47690525599184136 -0.6215143336146891 1.78001
      name "rock(1)"
      scale 2
    }
    Rock {
      translation 0.57 0.2 -0.03
      scale 2
    }
    Rock {
      translation 1.07 -0.06 -0.03
      rotation 0.38219697868777214 0.9227099485474618 0.05031719719419139 -2.899825307179586
      name "rock(9)"
      scale 2
    }
    Rock {
      translation 0.69 -0.27 -0.03
      rotation 0 1 0 0.261799
      name "rock(6)"
      scale 2
    }
    Rock {
      translation 0.917724 0.286832 -0.03
      rotation 0 0 1 1.309
      name "rock(4)"
      scale 2
    }
    Rock {
      translation 0.73 -0.03 -0.03
      rotation 0.09965723288844494 0.12987604286112467 -0.986509325563501 -1.8456953071795859
      name "rock(2)"
      scale 2
    }
  ]
}
